[2025-06-22T00:31:34.700+0000] {local_task_job_runner.py:120} INFO - ::group::Pre task execution logs
[2025-06-22T00:31:34.718+0000] {taskinstance.py:2076} INFO - Dependencies all met for dep_context=non-requeueable deps ti=<TaskInstance: deepai_crawler_10min.crawl_business scheduled__2025-06-22T00:10:00+00:00 [queued]>
[2025-06-22T00:31:34.728+0000] {taskinstance.py:2076} INFO - Dependencies all met for dep_context=requeueable deps ti=<TaskInstance: deepai_crawler_10min.crawl_business scheduled__2025-06-22T00:10:00+00:00 [queued]>
[2025-06-22T00:31:34.728+0000] {taskinstance.py:2306} INFO - Starting attempt 2 of 3
[2025-06-22T00:31:34.744+0000] {taskinstance.py:2330} INFO - Executing <Task(PythonOperator): crawl_business> on 2025-06-22 00:10:00+00:00
[2025-06-22T00:31:34.754+0000] {warnings.py:112} WARNING - /home/***/.local/lib/python3.12/site-packages/***/task/task_runner/standard_task_runner.py:61: DeprecationWarning: This process (pid=133) is multi-threaded, use of fork() may lead to deadlocks in the child.
  pid = os.fork()

[2025-06-22T00:31:34.756+0000] {standard_task_runner.py:63} INFO - Started process 171 to run task
[2025-06-22T00:31:34.758+0000] {standard_task_runner.py:90} INFO - Running: ['***', 'tasks', 'run', 'deepai_crawler_10min', 'crawl_business', 'scheduled__2025-06-22T00:10:00+00:00', '--job-id', '149', '--raw', '--subdir', 'DAGS_FOLDER/dags.py', '--cfg-path', '/tmp/tmp10nmzxzn']
[2025-06-22T00:31:34.762+0000] {standard_task_runner.py:91} INFO - Job 149: Subtask crawl_business
[2025-06-22T00:31:34.813+0000] {task_command.py:426} INFO - Running <TaskInstance: deepai_crawler_10min.crawl_business scheduled__2025-06-22T00:10:00+00:00 [running]> on host 5471b5a2dbbe
[2025-06-22T00:31:34.920+0000] {taskinstance.py:2648} INFO - Exporting env vars: AIRFLOW_CTX_DAG_OWNER='***' AIRFLOW_CTX_DAG_ID='deepai_crawler_10min' AIRFLOW_CTX_TASK_ID='crawl_business' AIRFLOW_CTX_EXECUTION_DATE='2025-06-22T00:10:00+00:00' AIRFLOW_CTX_TRY_NUMBER='2' AIRFLOW_CTX_DAG_RUN_ID='scheduled__2025-06-22T00:10:00+00:00'
[2025-06-22T00:31:34.922+0000] {taskinstance.py:430} INFO - ::endgroup::
[2025-06-22T00:31:34.939+0000] {dags.py:169} INFO - Bắt đầu crawl category: business
[2025-06-22T00:31:35.061+0000] {crawler_deeplai.py:49} INFO - Đã kết nối thành công với MongoDB: deeplearning_ai_news
[2025-06-22T00:31:35.062+0000] {dags.py:177} ERROR - Lỗi khi crawl category business: 'DeepLearningAICrawler' object has no attribute 'lf'
[2025-06-22T00:31:35.063+0000] {taskinstance.py:441} INFO - ::group::Post task execution logs
[2025-06-22T00:31:35.064+0000] {taskinstance.py:2905} ERROR - Task failed with exception
Traceback (most recent call last):
  File "/home/airflow/.local/lib/python3.12/site-packages/airflow/models/taskinstance.py", line 460, in _execute_task
    result = _execute_callable(context=context, **execute_callable_kwargs)
             ^^^^^^^^^^^^^^^^^^^^^^^^^^^^^^^^^^^^^^^^^^^^^^^^^^^^^^^^^^^^^
  File "/home/airflow/.local/lib/python3.12/site-packages/airflow/models/taskinstance.py", line 432, in _execute_callable
    return execute_callable(context=context, **execute_callable_kwargs)
           ^^^^^^^^^^^^^^^^^^^^^^^^^^^^^^^^^^^^^^^^^^^^^^^^^^^^^^^^^^^^
  File "/home/airflow/.local/lib/python3.12/site-packages/airflow/models/baseoperator.py", line 401, in wrapper
    return func(self, *args, **kwargs)
           ^^^^^^^^^^^^^^^^^^^^^^^^^^^
  File "/home/airflow/.local/lib/python3.12/site-packages/airflow/operators/python.py", line 235, in execute
    return_value = self.execute_callable()
                   ^^^^^^^^^^^^^^^^^^^^^^^
  File "/home/airflow/.local/lib/python3.12/site-packages/airflow/operators/python.py", line 252, in execute_callable
    return self.python_callable(*self.op_args, **self.op_kwargs)
           ^^^^^^^^^^^^^^^^^^^^^^^^^^^^^^^^^^^^^^^^^^^^^^^^^^^^^
  File "/opt/airflow/dags/dags.py", line 172, in crawl_deepai_category
    asyncio.run(_crawl_deepai_category(category_url, category_name, max_articles, min_articles_threshold, max_load_more_clicks))
  File "/home/airflow/.local/lib/python3.12/site-packages/nest_asyncio.py", line 30, in run
    return loop.run_until_complete(task)
           ^^^^^^^^^^^^^^^^^^^^^^^^^^^^^
  File "/home/airflow/.local/lib/python3.12/site-packages/nest_asyncio.py", line 98, in run_until_complete
    return f.result()
           ^^^^^^^^^^
  File "/usr/local/lib/python3.12/asyncio/futures.py", line 203, in result
    raise self._exception.with_traceback(self._exception_tb)
  File "/usr/local/lib/python3.12/asyncio/tasks.py", line 314, in __step_run_and_handle_result
    result = coro.send(None)
             ^^^^^^^^^^^^^^^
  File "/opt/airflow/dags/dags.py", line 185, in _crawl_deepai_category
    crawler = DeepLearningAICrawler(
              ^^^^^^^^^^^^^^^^^^^^^^
  File "/opt/airflow/dags/deeplearning_ai/crawler_deeplai.py", line 41, in __init__
    self.summarizer = ArticleSummarizer(lf=self.lf,handler=self.handler)
                                           ^^^^^^^
AttributeError: 'DeepLearningAICrawler' object has no attribute 'lf'
[2025-06-22T00:31:35.075+0000] {taskinstance.py:1206} INFO - Marking task as UP_FOR_RETRY. dag_id=deepai_crawler_10min, task_id=crawl_business, run_id=scheduled__2025-06-22T00:10:00+00:00, execution_date=20250622T001000, start_date=20250622T003134, end_date=20250622T003135
[2025-06-22T00:31:35.089+0000] {standard_task_runner.py:110} ERROR - Failed to execute job 149 for task crawl_business ('DeepLearningAICrawler' object has no attribute 'lf'; 171)
[2025-06-22T00:31:35.133+0000] {local_task_job_runner.py:240} INFO - Task exited with return code 1
[2025-06-22T00:31:35.156+0000] {taskinstance.py:3503} INFO - 0 downstream tasks scheduled from follow-on schedule check
[2025-06-22T00:31:35.159+0000] {local_task_job_runner.py:222} INFO - ::endgroup::
